Workbook

Sheet Resumen
A1: Resumen de reliquias
A2: Se actualiza solo al cambiar los desplegables de Estado.
A4: Clase | B4: Total | C4: Existentes | D4: Nuevas | E4: Pendiente | F4: Aprobada | G4: Ajustar | H4: Rechazada
A5: Neutral | B5: =COUNTIF(Reliquias!$C$5:$C$159,A5) -> 84 | C5: =COUNTIFS(Reliquias!$C$5:$C$159,A5,Reliquias!$H$5:$H$159,"Existente") -> 25 | D5: =B5-C5 -> 59 | E5: =COUNTIFS(Reliquias!$C$5:$C$159,$A5,Reliquias!$I$5:$I$159,"Pendiente") -> 0 | F5: =COUNTIFS(Reliquias!$C$5:$C$159,$A5,Reliquias!$I$5:$I$159,"Aprobada") -> 84 | G5: =COUNTIFS(Reliquias!$C$5:$C$159,$A5,Reliquias!$I$5:$I$159,"Ajustar") -> 0 | H5: =COUNTIFS(Reliquias!$C$5:$C$159,$A5,Reliquias!$I$5:$I$159,"Rechazada") -> 0
A6: Guerrera | B6: =COUNTIF(Reliquias!$C$5:$C$159,A6) -> 23 | C6: =COUNTIFS(Reliquias!$C$5:$C$159,A6,Reliquias!$H$5:$H$159,"Existente") -> 5 | D6: =B6-C6 -> 18 | E6: =COUNTIFS(Reliquias!$C$5:$C$159,$A6,Reliquias!$I$5:$I$159,"Pendiente") -> 0 | F6: =COUNTIFS(Reliquias!$C$5:$C$159,$A6,Reliquias!$I$5:$I$159,"Aprobada") -> 23 | G6: =COUNTIFS(Reliquias!$C$5:$C$159,$A6,Reliquias!$I$5:$I$159,"Ajustar") -> 0 | H6: =COUNTIFS(Reliquias!$C$5:$C$159,$A6,Reliquias!$I$5:$I$159,"Rechazada") -> 0
A7: Mago | B7: =COUNTIF(Reliquias!$C$5:$C$159,A7) -> 18 | C7: =COUNTIFS(Reliquias!$C$5:$C$159,A7,Reliquias!$H$5:$H$159,"Existente") -> 0 | D7: =B7-C7 -> 18 | E7: =COUNTIFS(Reliquias!$C$5:$C$159,$A7,Reliquias!$I$5:$I$159,"Pendiente") -> 0 | F7: =COUNTIFS(Reliquias!$C$5:$C$159,$A7,Reliquias!$I$5:$I$159,"Aprobada") -> 18 | G7: =COUNTIFS(Reliquias!$C$5:$C$159,$A7,Reliquias!$I$5:$I$159,"Ajustar") -> 0 | H7: =COUNTIFS(Reliquias!$C$5:$C$159,$A7,Reliquias!$I$5:$I$159,"Rechazada") -> 0
A8: Pícara | B8: =COUNTIF(Reliquias!$C$5:$C$159,A8) -> 30 | C8: =COUNTIFS(Reliquias!$C$5:$C$159,A8,Reliquias!$H$5:$H$159,"Existente") -> 12 | D8: =B8-C8 -> 18 | E8: =COUNTIFS(Reliquias!$C$5:$C$159,$A8,Reliquias!$I$5:$I$159,"Pendiente") -> 0 | F8: =COUNTIFS(Reliquias!$C$5:$C$159,$A8,Reliquias!$I$5:$I$159,"Aprobada") -> 30 | G8: =COUNTIFS(Reliquias!$C$5:$C$159,$A8,Reliquias!$I$5:$I$159,"Ajustar") -> 0 | H8: =COUNTIFS(Reliquias!$C$5:$C$159,$A8,Reliquias!$I$5:$I$159,"Rechazada") -> 0
A9: Total | B9: =SUM(B5:B8) -> 155 | C9: =SUM(C5:C8) -> 42 | D9: =SUM(D5:D8) -> 113 | E9: =SUM(E5:E8) -> 0 | F9: =SUM(F5:F8) -> 155 | G9: =SUM(G5:G8) -> 0 | H9: =SUM(H5:H8) -> 0
A11: Por rareza (nuevas)
A12: Rareza | B12: Nuevas
A13: Común | B13: =COUNTIFS(Reliquias!$D$5:$D$159,A13,Reliquias!$H$5:$H$159,"<>Existente") -> 23
A14: Poco común | B14: =COUNTIFS(Reliquias!$D$5:$D$159,A14,Reliquias!$H$5:$H$159,"<>Existente") -> 28
A15: Rara | B15: =COUNTIFS(Reliquias!$D$5:$D$159,A15,Reliquias!$H$5:$H$159,"<>Existente") -> 32
A16: Épica | B16: =COUNTIFS(Reliquias!$D$5:$D$159,A16,Reliquias!$H$5:$H$159,"<>Existente") -> 19
A17: Legendaria | B17: =COUNTIFS(Reliquias!$D$5:$D$159,A17,Reliquias!$H$5:$H$159,"<>Existente") -> 11

Sheet Reliquias
A1: Reliquias de Last Wish
A2: Celdas amarillas para rellenar: Estado (desplegable) y Comentarios. Las 42 reliquias que ya están en el juego aparecen como Aprobadas solo para tener el registro. Columna «Efecto fuerte»: robar cartas, ganar maná, abaratar cartas y eliminar cartas son efectos muy poderosos; deben dar poco o tener una condición difícil (ver hoja «Reglas de equilibrio»).
A4: # | B4: Reliquia | C4: Clase | D4: Rareza | E4: Efecto | F4: Categoría | G4: Efecto fuerte | H4: Origen | I4: Estado | J4: Comentarios
A5: 1 | B5: Anillo de Oro | C5: Neutral | D5: Común | E5: +15 de oro extra por victoria de combate. | F5: — | H5: Existente | I5: Aprobada
A6: 2 | B6: Poción de Sangre | C6: Neutral | D6: Común | E6: Recupera 8 HP después de cada combate. | F6: — | H6: Existente | I6: Aprobada
A7: 3 | B7: Amuleto de Vitalidad | C7: Neutral | D7: Común | E7: +10 de HP máximo permanente. | F7: — | H7: Existente | I7: Aprobada
A8: 4 | B8: Máscara del Ladrón | C8: Neutral | D8: Común | E8: +25% de oro en los combates y la tienda es un 10% más barata. | F8: — | H8: Existente | I8: Aprobada
A9: 5 | B9: Cicatriz | C9: Neutral | D9: Común | E9: Empiezas cada combate con 1 de Fuerza. | F9: — | H9: Existente | I9: Aprobada
A10: 6 | B10: Brazal de Guerra | C10: Neutral | D10: Común | E10: Al empezar cada combate ganas 8 de escudo. | F10: — | H10: Existente | I10: Aprobada
A11: 7 | B11: Orbe de Fuego | C11: Neutral | D11: Poco común | E11: +2 de daño en todos los ataques. | F11: — | H11: Existente | I11: Aprobada
A12: 8 | B12: Corazón de Hierro | C12: Neutral | D12: Poco común | E12: +15 de HP máximo permanente. | F12: — | H12: Existente | I12: Aprobada
A13: 9 | B13: Moneda de la Suerte | C13: Neutral | D13: Poco común | E13: Si un efecto al azar golpea dos veces seguidas al mismo enemigo, ganas 1 de maná (una vez por turno). | F13: — | G13: Maná | H13: Existente | I13: Aprobada
A14: 10 | B14: Herradura de Plata | C14: Neutral | D14: Poco común | E14: +30 de suerte. | F14: — | H14: Existente | I14: Aprobada
A15: 11 | B15: Tótem Roto | C15: Neutral | D15: Rara | E15: +1 carta robada al inicio de cada turno. | F15: — | G15: Robo | H15: Existente | I15: Aprobada
A16: 12 | B16: Piedra de Energía | C16: Neutral | D16: Rara | E16: +1 carta robada al inicio de cada turno. | F16: — | G16: Robo | H16: Existente | I16: Aprobada
A17: 13 | B17: Guante de Seda | C17: Neutral | D17: Rara | E17: La tercera carta que juegas cada turno cuesta 0. | F17: — | G17: Maná | H17: Existente | I17: Aprobada
A18: 14 | B18: Botas Silenciosas | C18: Neutral | D18: Rara | E18: En el primer turno de cada combate robas 2 cartas extra. | F18: — | G18: Robo | H18: Existente | I18: Aprobada
A19: 15 | B19: Amuleto de Combate | C19: Neutral | D19: Épica | E19: +1 maná máximo al inicio del combate. | F19: — | G19: Maná | H19: Existente | I19: Aprobada
A20: 16 | B20: Hilo de Araña | C20: Neutral | D20: Épica | E20: Si terminas el turno sin cartas en la mano, ganas 6 de escudo. | F20: — | H20: Existente | I20: Aprobada
A21: 17 | B21: Llave Maestra | C21: Neutral | D21: Épica | E21: Las salas del tesoro te dejan elegir entre 2 reliquias. | F21: — | H21: Existente | I21: Aprobada
A22: 18 | B22: Interés Compuesto | C22: Neutral | D22: Épica | E22: Cada vez que ganas oro, ganas además un 10% de tu oro total. | F22: — | H22: Existente | I22: Aprobada
A23: 19 | B23: Escudo Espectral | C23: Neutral | D23: Legendaria | E23: Sobrevive una vez con 1 HP a un golpe fatal. | F23: — | H23: Existente | I23: Aprobada
A24: 20 | B24: Trébol de Siete Hojas | C24: Neutral | D24: Legendaria | E24: +100 de suerte: muchas más cartas y reliquias doradas y de mayor rareza. | F24: — | H24: Existente | I24: Aprobada
A25: 21 | B25: Panacea | C25: Neutral | D25: Legendaria | E25: Eres inmune a cualquier debuff de los enemigos. | F25: — | H25: Existente | I25: Aprobada
A26: 22 | B26: Fuente Eterna | C26: Neutral | D26: Legendaria | E26: Al inicio de cada turno ganas 1 de maná máximo. | F26: — | G26: Maná | H26: Existente | I26: Aprobada
A27: 23 | B27: Ankh | C27: Neutral | D27: Legendaria | E27: Al recibir un golpe fatal, revives con toda tu vida (una vez). | F27: — | H27: Existente | I27: Aprobada
A28: 24 | B28: Espejo Singular | C28: Neutral | D28: Legendaria | E28: Al obtenerla, elimina todas tus cartas repetidas: te quedas con una copia de cada carta. | F28: — | G28: Remover | H28: Existente | I28: Aprobada
A29: 25 | B29: Reloj Roto | C29: Neutral | D29: Legendaria | E29: Una vez por combate, al quedarte en 0 de maná con cartas en la mano, recuperas todo el maná. | F29: — | G29: Maná | H29: Existente | I29: Aprobada
A30: 26 | B30: Colmillo de Hierro | C30: Guerrera | D30: Poco común | E30: Tu primer ataque de cada turno te cura 2. | F30: — | H30: Existente | I30: Aprobada
A31: 27 | B31: Venda Empapada | C31: Guerrera | D31: Poco común | E31: La primera vez que pierdes vida en tu turno, robas 1 carta. | F31: — | G31: Robo | H31: Existente | I31: Aprobada
A32: 28 | B32: Copa de Sangre | C32: Guerrera | D32: Rara | E32: Todas tus curaciones en combate curan 2 más. | F32: — | H32: Existente | I32: Aprobada
A33: 29 | B33: Estandarte Desgarrado | C33: Guerrera | D33: Épica | E33: Cada 3 veces que activas Furia, ganas 1 de Fuerza. | F33: — | H33: Existente | I33: Aprobada
A34: 30 | B34: Corazón de Titán | C34: Guerrera | D34: Legendaria | E34: La curación que sobrepasa tu vida máxima te da el doble de escudo. | F34: — | H34: Existente | I34: Aprobada
A35: 31 | B35: Saco de Trapos | C35: Pícara | D35: Común | E35: Cada vez que activas un Despojo, ganas 2 de escudo. | F35: — | H35: Existente | I35: Aprobada
A36: 32 | B36: Bolsa de Dagas | C36: Pícara | D36: Común | E36: Al inicio de cada combate, mete 2 Dagas Ocultas en tu pila de robo. | F36: — | H36: Existente | I36: Aprobada
A37: 33 | B37: Broche de Evasión | C37: Pícara | D37: Poco común | E37: Cada vez que activas un Combo, ganas 1 de bloqueo. | F37: — | H37: Existente | I37: Aprobada
A38: 34 | B38: Cuchillo Arrojadizo | C38: Pícara | D38: Poco común | E38: Cada vez que activas un Combo, inflige 1 de daño a un enemigo al azar. | F38: — | H38: Existente | I38: Aprobada
A39: 35 | B39: Pañuelo del Duelista | C39: Pícara | D39: Poco común | E39: Cuando una carta activa su Combo, hace +2 de daño y da +2 de escudo. | F39: — | H39: Existente | I39: Aprobada
A40: 36 | B40: Garfio | C40: Pícara | D40: Poco común | E40: La primera vez que activas un Despojo cada turno, robas 1 carta. | F40: — | G40: Robo | H40: Existente | I40: Aprobada
A41: 37 | B41: Vaina Afilada | C41: Pícara | D41: Poco común | E41: Tus Dagas Ocultas hacen +2 de daño. | F41: — | H41: Existente | I41: Aprobada
...

Sheet Reglas de equilibrio
A1: Reglas de equilibrio — efectos muy fuertes
A3: Efecto | B3: Por qué es fuerte | C3: Límite recomendado
A4: Robar cartas | B4: Muy fuerte: más opciones cada turno y llegas antes a tus mejores cartas. | C4: Cartas: robar 1, como mucho 2. Reliquias: 1 carta, una vez por turno o por combate, o detrás de una condición difícil (cada 3 Vacíos, pila de robo vacía…).
A5: Ganar maná | B5: Muy fuerte: cada maná es una carta más jugada por turno. | C5: Cartas: +1 de maná como mucho. Reliquias: +1 con condición difícil, una vez por turno o por combate, o con una contrapartida clara (Contrato Maldito).
A6: Abaratar cartas | B6: Equivale a ganar maná. | C6: Misma regla que el maná: 1 de descuento, una vez por turno y con condición.
A7: Eliminar cartas del mazo | B7: Fuerte: un mazo más pequeño llega antes a sus combos y a las condiciones de victoria. | C7: Normalmente 1 carta. Eliminar más (Tijeras del Sastre: 3) solo en Legendaria.
A8: Excepción | B8: Con condiciones complicadas se puede dar algo más. | C8: Cuanto más difícil o arriesgada sea la condición, más puede dar el efecto.
